<robot name="kuka_lwr_4plus" xmlns:controller="http://playerstage.sourceforge.net/gazebo/xmlschema/#controller" xmlns:interface="http://playerstage.sourceforge.net/gazebo/xmlschema/#interface" xmlns:sensor="http://playerstage.sourceforge.net/gazebo/xmlschema/#sensor" xmlns:xacro="http://www.ros.org/wiki/xacro">
    <material name="DarkGrey">
        <color rgba="0.3 0.3 0.3 1.0" />
    </material>
    <material name="Red">
        <color rgba="0.3 0.3 0.3 1.0" />
    </material>
    <material name="Black">
        <color rgba="0 0 0 1.0" />
    </material>
    <material name="Orange">
        <color rgba="1.0 0.487 0 1.0" />
    </material>
    <material name="Silver">
        <color rgba="1.0 1.0 1.0 1.0" />
    </material>
    <material name="Grey">
        <color rgba="0.7 0.7 0.7 1.0" />
    </material>
    <material name="Blue">
        <color rgba="0.0 0.0 0.8 1.0" />
    </material>
    <material name="HandGray">
        <color rgba="0.953 0.996 0.694 1.0" />
    </material>
    <material name="SickBlue">
        <color rgba="0.3058 0.5921 0.7294 1.0" />
    </material>
    <link name="world" />
    <joint name="arm_world_joint" type="fixed">
        <origin rpy="0 0 0" xyz="0 0 0.01" />
        <parent link="world" />
        <child link="lwr_arm_base_link" />
    </joint>
    <link name="lwr_arm_base_link">
        <inertial>
            <mass value="1.2" />
            <origin rpy="0 0 0" xyz="0 0 0.055" />
            <inertia ixx="0.00229" ixy="0" ixz="0" iyy="0.00216" iyz="0" izz="0.00229" />
        </inertial>
        <visual>
            <origin rpy="0 0 0" xyz="0 0 0" />
            <geometry>
                <mesh filename="model://kuka_lwr_4plus/meshes/arm_base.dae" scale="100 100 100" />
            </geometry>
            <material name="Red" />
        </visual>
        <collision>
            <origin rpy="0 0 0" xyz="0 0 0.01" />
            <geometry>
                <mesh filename="model://kuka_lwr_4plus/meshes/convex/arm_base_convex.stl" scale="0.9 0.9 0.9" />
            </geometry>
        </collision>
    </link>
    <joint name="lwr_arm_0_joint" type="revolute">
        <origin rpy="0 0 0" xyz="0 0 0.11" />
        <axis xyz="0 0 1" />
        <limit effort="204" lower="-2.96705972839" upper="2.96705972839" velocity="1.91986217719" />
        <safety_controller k_position="100" k_velocity="2" soft_lower_limit="-2.93215314335" soft_upper_limit="2.93215314335" />
        <dynamics damping="5.0" friction="15.0"/>
        <parent link="lwr_arm_base_link" />
        <child link="lwr_arm_1_link" />
    </joint>
    <link name="lwr_arm_1_link">
        <inertial>
            <mass value="2.0" />
            <origin rpy="0 0 0" xyz="0 0 0.130" />
            <inertia ixx="0.0136666666667" ixy="0" ixz="0" iyy="0.0118666666667" iyz="0" izz="0.003" />
        </inertial>
        <visual>
            <origin rpy="0 0 3.14159265359" xyz="0 0 0" />
            <geometry>
                <mesh filename="model://kuka_lwr_4plus/meshes/arm_segment_a.dae" scale="100 100 100" />
            </geometry>
            <material name="Red" />
        </visual>
        <collision>
            <origin rpy="0 0 3.14159265359" xyz="0 0 0" />
            <geometry>
                <mesh filename="model://kuka_lwr_4plus/meshes/convex/arm_segment_a_convex.stl" scale="1.0 1.0 1.0" />
            </geometry>
        </collision>
    </link>
    <joint name="lwr_arm_1_joint" type="revolute">
        <origin rpy="0 0 0" xyz="0 0 0.20" />
        <axis xyz="0 -1 0" />
        <limit effort="306" lower="-2.09439510239" upper="2.09439510239" velocity="1.91986217719" />
        <safety_controller k_position="100" k_velocity="2" soft_lower_limit="-2.05948851735" soft_upper_limit="2.05948851735" />
        <dynamics damping="5.0" friction="15.0"/>
        <parent link="lwr_arm_1_link" />
        <child link="lwr_arm_2_link" />
    </joint>
    <link name="lwr_arm_2_link">
        <inertial>
            <mass value="2.0" />
            <origin rpy="0 0 0" xyz="0 -0.06 0.07" />
            <inertia ixx="0.0136666666667" ixy="0" ixz="0" iyy="0.0118666666667" iyz="0" izz="0.003" />
        </inertial>
        <visual>
            <origin rpy="3.14159265359 0 3.14159265359" xyz="0 0 0.2" />
            <geometry>
                <mesh filename="model://kuka_lwr_4plus/meshes/arm_segment_b.dae" scale="100 100 100" />
            </geometry>
            <material name="Red" />
        </visual>
        <collision>
            <origin rpy="3.14159265359 0 3.14159265359" xyz="0 0 0.2" />
            <geometry>
                <mesh filename="model://kuka_lwr_4plus/meshes/convex/arm_segment_b_convex.stl" scale="1.0 1.0 1.0" />
            </geometry>
        </collision>
    </link>
    <joint name="lwr_arm_2_joint" type="revolute">
        <origin rpy="0 0 0" xyz="0 0 0.20" />
        <axis xyz="0 0 1" />
        <limit effort="204" lower="-2.96705972839" upper="2.96705972839" velocity="2.26892802759" />
        <safety_controller k_position="100" k_velocity="2" soft_lower_limit="-2.93215314335" soft_upper_limit="2.93215314335" />
        <dynamics damping="3.0" friction="15.0"/>
        <parent link="lwr_arm_2_link" />
        <child link="lwr_arm_3_link" />
    </joint>
    <link name="lwr_arm_3_link">
        <inertial>
            <mass value="2.0" />
            <origin rpy="0 0 0" xyz="0 -0.06 0.130" />
            <inertia ixx="0.0136666666667" ixy="0" ixz="0" iyy="0.0118666666667" iyz="0" izz="0.003" />
        </inertial>
        <visual>
            <origin rpy="0 0 0" xyz="0 0 0" />
            <geometry>
                <mesh filename="model://kuka_lwr_4plus/meshes/arm_segment_a.dae" scale="100 100 100" />
            </geometry>
            <material name="Red" />
        </visual>
        <collision>
            <origin rpy="0 0 0" xyz="0 0 0" />
            <geometry>
                <mesh filename="model://kuka_lwr_4plus/meshes/convex/arm_segment_a_convex.stl" scale="1.0 1.0 1.0" />
            </geometry>
        </collision>
    </link>
    <joint name="lwr_arm_3_joint" type="revolute">
        <origin rpy="0 0 0" xyz="0 0 0.20" />
        <axis xyz="0 1 0" />
        <limit effort="306" lower="-2.09439510239" upper="2.09439510239" velocity="2.26892802759" />
        <safety_controller k_position="100" k_velocity="2" soft_lower_limit="-2.05948851735" soft_upper_limit="2.05948851735" />
        <dynamics damping="3.0" friction="15.0"/>
        <parent link="lwr_arm_3_link" />
        <child link="lwr_arm_4_link" />
    </joint>
    <link name="lwr_arm_4_link">
        <inertial>
            <mass value="2.0" />
            <origin rpy="0 0 0" xyz="0 0.06 0.07" />
            <inertia ixx="0.0136666666667" ixy="0" ixz="0" iyy="0.0118666666667" iyz="0" izz="0.003" />
        </inertial>
        <visual>
            <origin rpy="0 3.14159265359 3.14159265359" xyz="0 0 0.2" />
            <geometry>
                <mesh filename="model://kuka_lwr_4plus/meshes/arm_segment_b.dae" scale="100 100 100" />
            </geometry>
            <material name="Red" />
        </visual>
        <collision>
            <origin rpy="0 3.14159265359 3.14159265359" xyz="0 0 0.2" />
            <geometry>
                <mesh filename="model://kuka_lwr_4plus/meshes/convex/arm_segment_b_convex.stl" scale="1.0 1.0 1.0" />
            </geometry>
        </collision>
    </link>
    <joint name="lwr_arm_4_joint" type="revolute">
        <origin rpy="0 0 0" xyz="0 0 0.20" />
        <axis xyz="0 0 1" />
        <limit effort="204" lower="-2.96705972839" upper="2.96705972839" velocity="2.26892802759" />
        <safety_controller k_position="100" k_velocity="2" soft_lower_limit="-2.93215314335" soft_upper_limit="2.93215314335" />
        <dynamics damping="1.0" friction="15.0"/>
        <parent link="lwr_arm_4_link" />
        <child link="lwr_arm_5_link" />
    </joint>
    <link name="lwr_arm_5_link">
        <inertial>
            <mass value="2.0" />
            <origin rpy="0 0 0" xyz="0 0 0.124" />
            <inertia ixx="0.0126506666667" ixy="0" ixz="0" iyy="0.0108506666667" iyz="0" izz="0.003" />
        </inertial>
        <visual>
            <origin rpy="0 0 3.14159265359" xyz="0 0 0" />
            <geometry name="lwr_arm_5_geom">
                <mesh filename="model://kuka_lwr_4plus/meshes/arm_segment_last.dae" scale="100 100 100" />
            </geometry>
            <material name="Red" />
        </visual>
        <collision>
            <origin rpy="0 0 3.14159265359" xyz="0 0 0" />
            <geometry>
                <mesh filename="model://kuka_lwr_4plus/meshes/convex/arm_segment_last_convex.stl" scale="1.0 1.0 1.0" />
            </geometry>
        </collision>
    </link>
    <joint name="lwr_arm_5_joint" type="revolute">
        <origin rpy="0 0 0" xyz="0 0 0.19" />
        <axis xyz="0 -1 0" />
        <limit effort="306" lower="-2.09439510239" upper="2.09439510239" velocity="3.14159265359" />
        <safety_controller k_position="100" k_velocity="2" soft_lower_limit="-2.05948851735" soft_upper_limit="2.05948851735" />
        <dynamics damping="1.0" friction="15.0"/>
        <parent link="lwr_arm_5_link" />
        <child link="lwr_arm_6_link" />
    </joint>
    <link name="lwr_arm_6_link">
        <inertial>
            <mass value="1.0" />
            <origin rpy="0 0 0" xyz="0 0 0.0" />
            <inertia ixx="0.00260416666667" ixy="0" ixz="0" iyy="0.00260416666667" iyz="0" izz="0.00260416666667" />
        </inertial>
        <visual>
            <origin rpy="0 0 3.14159265359" xyz="0 0 0" />
            <geometry>
                <mesh filename="model://kuka_lwr_4plus/meshes/arm_wrist.dae" scale="100 100 100" />
            </geometry>
            <material name="Grey" />
        </visual>
        <collision>
            <origin rpy="0 0 3.14159265359" xyz="0 0 0" />
            <geometry>
                <mesh filename="model://kuka_lwr_4plus/meshes/convex/arm_wrist_convex.stl" scale="1.0 1.0 1.0" />
            </geometry>
        </collision>
    </link>
    <origin xyz="0 0 0" rpy="0 0 0" />
</robot>